<?xml version="1.0" encoding="UTF-8"?>
<!-- Generated by org.testng.reporters.JUnitReportReporter -->
<testsuite hostname="DESKTOP-K1L6537" failures="1" tests="4" name="letcodeProject.TestClass.Validate_test_data_using_data_provider" time="164.480" errors="0" timestamp="2023-01-19T15:24:13 IST" skipped="0">
  <testcase classname="letcodeProject.TestClass.Validate_test_data_using_data_provider" name="check_login_details_using_dataprovider" time="27.067">
    <failure message="expected [Error: There is no user record corresponding to this identifier. The user may have been deleted.] but found []" type="java.lang.AssertionError">
      <![CDATA[java.lang.AssertionError: expected [Error: There is no user record corresponding to this identifier. The user may have been deleted.] but found []
at org.testng.Assert.fail(Assert.java:99)
at org.testng.Assert.failNotEquals(Assert.java:1037)
at org.testng.Assert.assertEqualsImpl(Assert.java:140)
at org.testng.Assert.assertEquals(Assert.java:122)
at org.testng.Assert.assertEquals(Assert.java:629)
at org.testng.Assert.assertEquals(Assert.java:639)
at letcodeProject.TestClass.Validate_test_data_using_data_provider.check_login_details_using_dataprovider(Validate_test_data_using_data_provider.java:33)
at java.base/jdk.internal.reflect.DirectMethodHandleAccessor.invoke(DirectMethodHandleAccessor.java:104)
at java.base/java.lang.reflect.Method.invoke(Method.java:577)
at org.testng.internal.MethodInvocationHelper.invokeMethod(MethodInvocationHelper.java:133)
at org.testng.internal.TestInvoker.invokeMethod(TestInvoker.java:598)
at org.testng.internal.TestInvoker.invokeTestMethod(TestInvoker.java:173)
at org.testng.internal.MethodRunner.runInSequence(MethodRunner.java:46)
at org.testng.internal.TestInvoker$MethodInvocationAgent.invoke(TestInvoker.java:824)
at org.testng.internal.TestInvoker.invokeTestMethods(TestInvoker.java:146)
at org.testng.internal.TestMethodWorker.invokeTestMethods(TestMethodWorker.java:146)
at org.testng.internal.TestMethodWorker.run(TestMethodWorker.java:128)
at java.base/java.util.ArrayList.forEach(ArrayList.java:1511)
at org.testng.TestRunner.privateRun(TestRunner.java:794)
at org.testng.TestRunner.run(TestRunner.java:596)
at org.testng.SuiteRunner.runTest(SuiteRunner.java:377)
at org.testng.SuiteRunner.access$000(SuiteRunner.java:28)
at org.testng.SuiteRunner$SuiteWorker.run(SuiteRunner.java:418)
at org.testng.internal.thread.ThreadUtil.lambda$execute$0(ThreadUtil.java:64)
at java.base/java.util.concurrent.FutureTask.run(FutureTask.java:264)
at java.base/java.util.concurrent.ThreadPoolExecutor.runWorker(ThreadPoolExecutor.java:1136)
at java.base/java.util.concurrent.ThreadPoolExecutor$Worker.run(ThreadPoolExecutor.java:635)
at java.base/java.lang.Thread.run(Thread.java:833)
]]>
    </failure>
  </testcase> <!-- check_login_details_using_dataprovider -->
  <system-out/>
  <testcase classname="letcodeProject.TestClass.Validate_test_data_using_data_provider" name="check_login_details_using_dataprovider" time="70.321"/>
  <system-out/>
  <testcase classname="letcodeProject.TestClass.Validate_test_data_using_data_provider" name="check_login_details_using_dataprovider" time="35.363"/>
  <system-out/>
  <testcase classname="letcodeProject.TestClass.Validate_test_data_using_data_provider" name="check_login_details_using_dataprovider" time="31.729"/>
  <system-out/>
</testsuite> <!-- letcodeProject.TestClass.Validate_test_data_using_data_provider -->
